def anError() {
    throw new Exception("Error message");
    println("Never executed!");
}

def main(List<String> args) -> Int {
    try {
        anError();
    } catch(Exception ex) {
        println("Oh no!");
        println(ex.getMessage());
    }

    println("We resume here!");

    let List<String> list = null;

    return list.getSize();
}